<mujoco model="go2w">
  <compiler angle="radian" meshdir="meshs" autolimits="true" />
  <statistic center="0 0 0.1" extent="0.8" />
  <option cone="elliptic" impratio="100" timestep="0.005" />

  <default>
    <default class="go2w">
      <geom friction="0.4" margin="0.001" condim="1" />
      <joint axis="0 1 0" damping="0.1" armature="0.01" frictionloss="0.2" />
      <motor ctrlrange="-23.7 23.7" />
      <default class="abduction">
        <joint axis="1 0 0" range="-1.0472 1.0472" />
      </default>
      <default class="hip">
        <default class="front_hip">
          <joint range="-1.5708 3.4907" />
        </default>
        <default class="back_hip">
          <joint range="-0.5236 4.5379" />
        </default>
      </default>
      <default class="knee">
        <joint range="-2.7227 -0.83776" />
        <motor ctrlrange="-45.43 45.43" />
      </default>
      <default class="visual">
        <geom type="mesh" contype="0" conaffinity="0" group="2" />
      </default>
      <default class="collision">
        <geom group="3" />
        <default class="foot">
          <geom size="0.022" pos="-0.002 0 -0.2264" priority="1" condim="6"
            friction="0.8 0.02 0.01" />
        </default>
      </default>
      <default class="collision_visual">
        <geom type="mesh" group="2" priority="1" condim="6" friction="0.8 0.02 0.01" />
      </default>
    </default>

    <default class="wheel_site">
      <site type="box" size="0.086 0.08 0.086" rgba="1 0 1 0.0" />
    </default>
  </default>

  <visual>
    <global realtime="1" />
    <quality shadowsize="2048" numslices="18" offsamples="4" />
    <headlight diffuse="1 1 1" specular="0.5 0.5 0.5" active="1" />
  </visual>

  <asset>
    <material name="metal" rgba=".9 .95 .95 1" />
    <material name="black" rgba="0 0 0 1" />
    <material name="red" rgba=".9 .1 .1 1" />
    <material name="green" rgba=".1 .9 .1 1" />
    <material name="blue" rgba=".1 .1 .9 1" />
    <material name="yellow" rgba=".9 .9 .1 1" />
    <material name="white" rgba="1 1 1 1" />
    <material name="gray" rgba="0.671705 0.692426 0.774270 1" />

    <mesh file="base_0.obj" />
    <mesh file="base_1.obj" />
    <mesh file="base_2.obj" />
    <mesh file="base_3.obj" />
    <mesh file="base_4.obj" />
    <mesh file="hip_0.obj" />
    <mesh file="hip_1.obj" />
    <mesh file="thigh_0.obj" />
    <mesh file="thigh_1.obj" />
    <mesh file="thigh_mirror_0.obj" />
    <mesh file="thigh_mirror_1.obj" />
    <mesh file="calf_mirror_0.obj" />
    <mesh file="calf_mirror_1.obj" />
    <mesh file="calf.stl" />
    <mesh file="calf_mirror.stl" />
    <mesh file="foot.obj" />
    <mesh file="wheel.stl" />

    <mesh file="femto_bolt.STL" />
    <mesh file="femto_bolt_fixed.STL" />

    <mesh file="d435i_fix1.STL" />
    <mesh file="d435i_fix2.STL" />

    <material name="Black_Acrylic" rgba="0.070360 0.070360 0.070360 1" />
    <material name="Cameras_Gray" rgba="0.296138 0.296138 0.296138 1" />
    <material name="IR_Emitter_Lens" rgba="0.287440 0.665387 0.327778 1" />
    <material name="IR_Lens" rgba="0.035601 0.035601 0.035601 1" />
    <material name="IR_Rim" rgba="0.799102 0.806952 0.799103 1" />
    <material name="Metal_Casing" rgba="1 1 1 1" />
    <material name="RGB_Pupil" rgba="0.087140 0.002866 0.009346 1" />

    <mesh file="d435i_0.obj" />
    <mesh file="d435i_1.obj" />
    <mesh file="d435i_2.obj" />
    <mesh file="d435i_3.obj" />
    <mesh file="d435i_4.obj" />
    <mesh file="d435i_5.obj" />
    <mesh file="d435i_6.obj" />
    <mesh file="d435i_7.obj" />
    <mesh file="d435i_8.obj" />


    <material name="mocap_material" rgba="0.9 0 0 0.2" />
  </asset>

  <worldbody>

    <body name="base_link" pos="0 0 0.6" childclass="go2w">
      <site name="base_link" />
      <inertial pos="0.021112 0 -0.005366" quat="-0.000543471 0.713435 -0.00173769 0.700719"
        mass="6.921"
        diaginertia="0.107027 0.0980771 0.0244531" />
      <freejoint />
      <!-- <body pos="0.222 0 0.1" xyaxes="0 -1 0 -1 0 0">
        <geom mesh="femto_bolt" pos="-0.065 -0.21 -1" material="gray" class="visual" mass="0.1"/>
        <geom mesh="femto_bolt_fixed" pos="-0.065 -0.21 -1" material="red" class="visual" mass="0.1"/>
      </body> -->
      <body name="d435i_and_fix" pos="0.35 0.01 0.045" euler="0 -0.065449847 0">
        <geom mesh="d435i_fix1" material="red" class="collision_visual" mass="0.1" euler="0 0.2 0" />
        <body euler="0 0.2 0">
          <geom mesh="d435i_fix2" material="red" class="collision_visual" mass="0.1" />
          <camera name="RayCasterCamera" pos="0.045 0 0" xyaxes="0 -1 0 0 0 1" fovy="80" />
          <body name="d435i" xyaxes="0 1 0 0 0 1" pos="0.0434 -0.0115 0">
            <geom mesh="d435i_0" material="IR_Lens" class="collision_visual" />
            <geom mesh="d435i_1" material="IR_Emitter_Lens" class="collision_visual" />
            <geom mesh="d435i_2" material="IR_Rim" class="collision_visual" />
            <geom mesh="d435i_3" material="IR_Lens" class="collision_visual" />
            <geom mesh="d435i_4" material="Cameras_Gray" class="collision_visual" />
            <geom mesh="d435i_5" material="Black_Acrylic" class="collision_visual" />
            <geom mesh="d435i_6" material="Black_Acrylic" class="collision_visual" />
            <geom mesh="d435i_7" material="RGB_Pupil" class="collision_visual" />
            <geom mesh="d435i_8" mass="0.072" material="Metal_Casing" class="collision_visual" />
          </body>
        </body>
      </body>
      <camera name="RayCaster_yaw" pos="0.15 0 0" xyaxes="0 -1 0 1 0 0" />
      <geom mesh="base_0" material="black" class="visual" />
      <geom mesh="base_1" material="black" class="visual" />
      <geom mesh="base_2" material="black" class="visual" />
      <geom mesh="base_3" material="white" class="visual" />
      <geom mesh="base_4" material="gray" class="visual" />
      <geom size="0.1881 0.04675 0.057" type="box" class="collision" />
      <geom size="0.05 0.045" pos="0.285 0 0.01" type="cylinder" class="collision" />
      <geom size="0.047" pos="0.293 0 -0.06" class="collision" />
      <site name="imu" pos="-0.02557 0 0.04232" />
      <body name="FL_hip" pos="0.1934 0.0465 0">
        <inertial pos="-0.0054 0.00194 -0.000105" quat="0.497014 0.499245 0.505462 0.498237"
          mass="0.678"
          diaginertia="0.00088403 0.000596003 0.000479967" />
        <joint name="FL_hip_joint" class="abduction" />
        <geom mesh="hip_0" material="metal" class="visual" />
        <geom mesh="hip_1" material="gray" class="visual" />
        <geom size="0.046 0.02" pos="0 0.08 0" quat="1 1 0 0" type="cylinder" class="collision" />
        <body name="FL_thigh" pos="0 0.0955 0">
          <inertial pos="-0.00374 -0.0223 -0.0327" quat="0.829533 0.0847635 -0.0200632 0.551623"
            mass="1.152"
            diaginertia="0.00594973 0.00584149 0.000878787" />
          <joint name="FL_thigh_joint" class="front_hip" />
          <geom mesh="thigh_0" material="metal" class="visual" />
          <geom mesh="thigh_1" material="gray" class="visual" />
          <geom size="0.1065 0.01225 0.017" pos="0 0 -0.1065" quat="0.707107 0 0.707107 0"
            type="box" class="collision" />
          <body name="FL_calf" pos="0 0 -0.213">
            <inertial pos="0.00629595 -0.000622121 -0.141417"
              quat="0.710672 0.00154099 -0.00450087 0.703508"
              mass="0.241352" diaginertia="0.0014901 0.00146356 5.31397e-05" />
            <joint name="FL_calf_joint" class="knee" />
            <geom mesh="calf" material="gray" class="visual" />
            <geom size="0.012 0.06" pos="0.008 0 -0.06" quat="0.994493 0 -0.104807 0"
              type="cylinder" class="collision" />
            <geom size="0.011 0.0325" pos="0.02 0 -0.148" quat="0.999688 0 0.0249974 0"
              type="cylinder" class="collision" />

            <body name="FL_wheel_link" pos="0 0 -0.2264">
              <inertial pos="-0.0 0.04 -0.0"
                quat="0.661419 0.248219 0.250051 0.662108" mass="0.98"
                diaginertia="0.003 0.0016 0.0016" />
              <joint name="FL_foot_joint" pos="0 0 0" axis="0 1 0" />
              <site name="FL_foot_joint" pos="0 0 0" class="wheel_site" />
              <geom type="mesh" rgba="0.15 0.15 0.15 1" mesh="wheel" pos="0 0.0 0"
                quat="0.0 1.0 0.0 0.0" class="collision_visual" />
              <!-- <geom pos="0 0.0 0" quat="0.0 1.0 0.0 0.0" type="mesh" mesh="wheel" class="foot"
              /> -->
            </body>

          </body>
        </body>
      </body>
      <body name="FR_hip" pos="0.1934 -0.0465 0">
        <inertial pos="-0.0054 -0.00194 -0.000105" quat="0.498237 0.505462 0.499245 0.497014"
          mass="0.678"
          diaginertia="0.00088403 0.000596003 0.000479967" />
        <joint name="FR_hip_joint" class="abduction" />

        <geom mesh="hip_0" material="metal" class="visual" quat="4.63268e-05 1 0 0" />
        <geom mesh="hip_1" material="gray" class="visual" quat="4.63268e-05 1 0 0" />
        <geom size="0.046 0.02" pos="0 -0.08 0" quat="0.707107 0.707107 0 0" type="cylinder"
          class="collision" />
        <body name="FR_thigh" pos="0 -0.0955 0">
          <inertial pos="-0.00374 0.0223 -0.0327" quat="0.551623 -0.0200632 0.0847635 0.829533"
            mass="1.152"
            diaginertia="0.00594973 0.00584149 0.000878787" />
          <joint name="FR_thigh_joint" class="front_hip" />
          <geom mesh="thigh_mirror_0" material="metal" class="visual" />
          <geom mesh="thigh_mirror_1" material="gray" class="visual" />
          <geom size="0.1065 0.01225 0.017" pos="0 0 -0.1065" quat="0.707107 0 0.707107 0"
            type="box" class="collision" />
          <body name="FR_calf" pos="0 0 -0.213">
            <inertial pos="0.00629595 0.000622121 -0.141417"
              quat="0.703508 -0.00450087 0.00154099 0.710672"
              mass="0.241352" diaginertia="0.0014901 0.00146356 5.31397e-05" />
            <joint name="FR_calf_joint" class="knee" />
            <geom mesh="calf_mirror" material="gray" class="visual" />
            <geom size="0.013 0.06" pos="0.01 0 -0.06" quat="0.995004 0 -0.0998334 0"
              type="cylinder" class="collision" />
            <geom size="0.011 0.0325" pos="0.02 0 -0.148" quat="0.999688 0 0.0249974 0"
              type="cylinder" class="collision" />

            <body name="FR_wheel_link" pos="0 0 -0.2264">
              <inertial pos="-0.0 -0.04 -0.0"
                quat="0.661419 0.248219 0.250051 0.662108" mass="0.98"
                diaginertia="0.003 0.0016 0.0016" />
              <joint name="FR_foot_joint" pos="0 0 0" axis="0 1 0" />
              <site name="FR_foot_joint" class="wheel_site" />
              <geom type="mesh" rgba="0.15 0.15 0.15 1" mesh="wheel" pos="0 -0.0 0"
                class="collision_visual" />
              <!-- <geom pos="0 0.0 0" type="mesh" mesh="wheel" class="foot" /> -->
            </body>

          </body>
        </body>
      </body>
      <body name="RL_hip" pos="-0.1934 0.0465 0">
        <inertial pos="0.0054 0.00194 -0.000105" quat="0.505462 0.498237 0.497014 0.499245"
          mass="0.678"
          diaginertia="0.00088403 0.000596003 0.000479967" />
        <joint name="RL_hip_joint" class="abduction" />

        <geom mesh="hip_0" material="metal" class="visual" quat="4.63268e-05 0 1 0" />
        <geom mesh="hip_1" material="gray" class="visual" quat="4.63268e-05 0 1 0" />
        <geom size="0.046 0.02" pos="0 0.08 0" quat="0.707107 0.707107 0 0" type="cylinder"
          class="collision" />
        <body name="RL_thigh" pos="0 0.0955 0">
          <inertial pos="-0.00374 -0.0223 -0.0327" quat="0.829533 0.0847635 -0.0200632 0.551623"
            mass="1.152"
            diaginertia="0.00594973 0.00584149 0.000878787" />
          <joint name="RL_thigh_joint" class="back_hip" />
          <geom mesh="thigh_0" material="metal" class="visual" />
          <geom mesh="thigh_1" material="gray" class="visual" />
          <geom size="0.1065 0.01225 0.017" pos="0 0 -0.1065" quat="0.707107 0 0.707107 0"
            type="box" class="collision" />
          <body name="RL_calf" pos="0 0 -0.213">
            <inertial pos="0.00629595 -0.000622121 -0.141417"
              quat="0.710672 0.00154099 -0.00450087 0.703508"
              mass="0.241352" diaginertia="0.0014901 0.00146356 5.31397e-05" />
            <joint name="RL_calf_joint" class="knee" />
            <geom mesh="calf" material="gray" class="visual" />
            <geom size="0.013 0.06" pos="0.01 0 -0.06" quat="0.995004 0 -0.0998334 0"
              type="cylinder" class="collision" />
            <geom size="0.011 0.0325" pos="0.02 0 -0.148" quat="0.999688 0 0.0249974 0"
              type="cylinder" class="collision" />

            <body name="RL_wheel_link" pos="0 0 -0.2264">
              <inertial pos="-0.0 0.04 -0.0"
                quat="0.661419 0.248219 0.250051 0.662108" mass="0.98"
                diaginertia="0.003 0.0016 0.0016" />
              <joint name="RL_foot_joint" pos="0 0 0" axis="0 1 0" />
              <site name="RL_foot_joint" class="wheel_site" />
              <geom type="mesh" rgba="0.15 0.15 0.15 1" mesh="wheel" pos="0 0.0 0"
                quat="0.0 1.0 0.0 0.0" class="collision_visual" />
              <!-- <geom pos="0 0.0 0" quat="0.0 1.0 0.0 0.0" type="mesh" mesh="wheel" class="foot"
              /> -->
            </body>

          </body>
        </body>
      </body>
      <body name="RR_hip" pos="-0.1934 -0.0465 0">
        <inertial pos="0.0054 -0.00194 -0.000105" quat="0.499245 0.497014 0.498237 0.505462"
          mass="0.678"
          diaginertia="0.00088403 0.000596003 0.000479967" />
        <joint name="RR_hip_joint" class="abduction" />

        <geom mesh="hip_0" material="metal" class="visual"
          quat="2.14617e-09 4.63268e-05 4.63268e-05 -1" />
        <geom mesh="hip_1" material="gray" class="visual"
          quat="2.14617e-09 4.63268e-05 4.63268e-05 -1" />
        <geom size="0.046 0.02" pos="0 -0.08 0" quat="0.707107 0.707107 0 0" type="cylinder"
          class="collision" />
        <body name="RR_thigh" pos="0 -0.0955 0">
          <inertial pos="-0.00374 0.0223 -0.0327" quat="0.551623 -0.0200632 0.0847635 0.829533"
            mass="1.152"
            diaginertia="0.00594973 0.00584149 0.000878787" />
          <joint name="RR_thigh_joint" class="back_hip" />
          <geom mesh="thigh_mirror_0" material="metal" class="visual" />
          <geom mesh="thigh_mirror_1" material="gray" class="visual" />
          <geom size="0.1065 0.01225 0.017" pos="0 0 -0.1065" quat="0.707107 0 0.707107 0"
            type="box" class="collision" />
          <body name="RR_calf" pos="0 0 -0.213">
            <inertial pos="0.00629595 0.000622121 -0.141417"
              quat="0.703508 -0.00450087 0.00154099 0.710672"
              mass="0.241352" diaginertia="0.0014901 0.00146356 5.31397e-05" />
            <joint name="RR_calf_joint" class="knee" />
            <geom mesh="calf_mirror" material="gray" class="visual" />
            <geom size="0.013 0.06" pos="0.01 0 -0.06" quat="0.995004 0 -0.0998334 0"
              type="cylinder" class="collision" />
            <geom size="0.011 0.0325" pos="0.02 0 -0.148" quat="0.999688 0 0.0249974 0"
              type="cylinder" class="collision" />

            <body name="RR_wheel_link" pos="0 0 -0.2264">
              <inertial pos="-0.0 -0.04 -0.0"
                quat="0.661419 0.248219 0.250051 0.662108" mass="0.98"
                diaginertia="0.003 0.0016 0.0016" />
              <joint name="RR_foot_joint" pos="0 0 0" axis="0 1 0" />
              <site name="RR_foot_joint" class="wheel_site" />
              <geom type="mesh" rgba="0.15 0.15 0.15 1" mesh="wheel" pos="0 -0.00 0"
                class="collision_visual" />
              <!-- <geom pos="0 0.0 0" type="mesh" mesh="wheel" class="foot" /> -->
            </body>

          </body>
        </body>
      </body>

      <site name="FL_foot_joint_ref" pos="0.2 0.15 0" class="wheel_site" />
      <site name="FR_foot_joint_ref" pos="0.2 -0.15 0" class="wheel_site" />
      <site name="RL_foot_joint_ref" pos="-0.2 0.15 0" class="wheel_site" />
      <site name="RR_foot_joint_ref" pos="-0.2 -0.15 0" class="wheel_site" />
    </body>

    <light pos="0 0 1.5" dir="0 0 -1" directional="true" />
  </worldbody>

  <actuator>
    <motor name="FL_foot_joint_x" site="FL_foot_joint" refsite="base_link"
      gear="1 0 0 0 0 0" />
    <motor name="FL_foot_joint_y" site="FL_foot_joint" refsite="base_link"
      gear="0 1 0 0 0 0" />
    <motor name="FL_foot_joint_z" site="FL_foot_joint" refsite="base_link"
      gear="0 0 1 0 0 0" />

    <motor name="FR_foot_joint_x" site="FR_foot_joint" refsite="base_link"
      gear="1 0 0 0 0 0" />
    <motor name="FR_foot_joint_y" site="FR_foot_joint" refsite="base_link"
      gear="0 1 0 0 0 0" />
    <motor name="FR_foot_joint_z" site="FR_foot_joint" refsite="base_link"
      gear="0 0 1 0 0 0" />

    <motor name="RL_foot_joint_x" site="RL_foot_joint" refsite="base_link"
      gear="1 0 0 0 0 0" />
    <motor name="RL_foot_joint_y" site="RL_foot_joint" refsite="base_link"
      gear="0 1 0 0 0 0" />
    <motor name="RL_foot_joint_z" site="RL_foot_joint" refsite="base_link"
      gear="0 0 1 0 0 0" />

    <motor name="RR_foot_joint_x" site="RR_foot_joint" refsite="base_link"
      gear="1 0 0 0 0 0" />
    <motor name="RR_foot_joint_y" site="RR_foot_joint" refsite="base_link"
      gear="0 1 0 0 0 0" />
    <motor name="RR_foot_joint_z" site="RR_foot_joint" refsite="base_link"
      gear="0 0 1 0 0 0" />


    <motor name="FR_hip_joint" joint="FR_hip_joint" forcerange="-23.5 23.5" />
    <motor name="FR_thigh_joint" joint="FR_thigh_joint" forcerange="-23.5 23.5" />
    <motor name="FR_calf_joint" joint="FR_calf_joint" forcerange="-23.5 23.5" />
    <motor name="FL_hip_joint" joint="FL_hip_joint" forcerange="-23.5 23.5" />
    <motor name="FL_thigh_joint" joint="FL_thigh_joint" forcerange="-23.5 23.5" />
    <motor name="FL_calf_joint" joint="FL_calf_joint" forcerange="-23.5 23.5" />
    <motor name="RR_hip_joint" joint="RR_hip_joint" forcerange="-23.5 23.5" />
    <motor name="RR_thigh_joint" joint="RR_thigh_joint" forcerange="-23.5 23.5" />
    <motor name="RR_calf_joint" joint="RR_calf_joint" forcerange="-23.5 23.5" />
    <motor name="RL_hip_joint" joint="RL_hip_joint" forcerange="-23.5 23.5" />
    <motor name="RL_thigh_joint" joint="RL_thigh_joint" forcerange="-23.5 23.5" />
    <motor name="RL_calf_joint" joint="RL_calf_joint" forcerange="-23.5 23.5" />


    <velocity name="FR_foot_joint" joint="FR_foot_joint" kv="5" forcerange="-23.5 23.5" />
    <velocity name="FL_foot_joint" joint="FL_foot_joint" kv="5" forcerange="-23.5 23.5" />
    <velocity name="RR_foot_joint" joint="RR_foot_joint" kv="5" forcerange="-23.5 23.5" />
    <velocity name="RL_foot_joint" joint="RL_foot_joint" kv="5" forcerange="-23.5 23.5" />
  </actuator>

  <sensor>
    <jointpos name="FL_hip_joint_pos" joint="FL_hip_joint" />
    <jointpos name="FR_hip_joint_pos" joint="FR_hip_joint" />
    <jointpos name="RL_hip_joint_pos" joint="RL_hip_joint" />
    <jointpos name="RR_hip_joint_pos" joint="RR_hip_joint" />
    <jointpos name="FL_thigh_joint_pos" joint="FL_thigh_joint" />
    <jointpos name="FR_thigh_joint_pos" joint="FR_thigh_joint" />
    <jointpos name="RL_thigh_joint_pos" joint="RL_thigh_joint" />
    <jointpos name="RR_thigh_joint_pos" joint="RR_thigh_joint" />
    <jointpos name="FL_calf_joint_pos" joint="FL_calf_joint" />
    <jointpos name="FR_calf_joint_pos" joint="FR_calf_joint" />
    <jointpos name="RL_calf_joint_pos" joint="RL_calf_joint" />
    <jointpos name="RR_calf_joint_pos" joint="RR_calf_joint" />


    <jointvel name="FL_hip_joint_vel" joint="FL_hip_joint" />
    <jointvel name="FR_hip_joint_vel" joint="FR_hip_joint" />
    <jointvel name="RL_hip_joint_vel" joint="RL_hip_joint" />
    <jointvel name="RR_hip_joint_vel" joint="RR_hip_joint" />
    <jointvel name="FL_thigh_joint_vel" joint="FL_thigh_joint" />
    <jointvel name="FR_thigh_joint_vel" joint="FR_thigh_joint" />
    <jointvel name="RL_thigh_joint_vel" joint="RL_thigh_joint" />
    <jointvel name="RR_thigh_joint_vel" joint="RR_thigh_joint" />
    <jointvel name="FL_calf_joint_vel" joint="FL_calf_joint" />
    <jointvel name="FR_calf_joint_vel" joint="FR_calf_joint" />
    <jointvel name="RL_calf_joint_vel" joint="RL_calf_joint" />
    <jointvel name="RR_calf_joint_vel" joint="RR_calf_joint" />


    <framequat name="imu_quat" objtype="site" objname="imu" noise="0.0" />
    <gyro name="imu_gyro" site="imu" noise="0.0" />
    <accelerometer name="imu_acc" site="imu" />

    <framepos name="frame_pos" objtype="site" objname="imu" />
    <framelinvel name="frame_vel" objtype="site" objname="imu" />
    <subtreecom name="subtreecom" body="base_link" />

    <force name="FL_foot_joint_force" site="FL_foot_joint" />
    <force name="FR_foot_joint_force" site="FR_foot_joint" />
    <force name="RL_foot_joint_force" site="RL_foot_joint" />
    <force name="RR_foot_joint_force" site="RR_foot_joint" />

    <framepos name="FL_foot_joint_pos" objtype="site" objname="FL_foot_joint" />
    <framepos name="FR_foot_joint_pos" objtype="site" objname="FR_foot_joint" />
    <framepos name="RL_foot_joint_pos" objtype="site" objname="RL_foot_joint" />
    <framepos name="RR_foot_joint_pos" objtype="site" objname="RR_foot_joint" />
  </sensor>

  <keyframe>
    <key name="init" time="0.0"
      qpos="0 0 0.45 1 0 0 0  0.00571868 0.608813 -1.21763 0
                              0.00571868 0.608813 -1.21763 0
                              0.00571868 0.608813 -1.21763 0
                              0.00571868 0.608813 -1.21763 0" />
  </keyframe>

  <include file="trench_box_terrain.xml" />
  <include file="go2w_ray_caster.xml" />
</mujoco>